<?xml version="1.0"?>
<robot xmlns:xacro="http://www.ros.org/wiki/xacro">

    <material name="white">
        <color rgba="1 1 1 1" />
    </material>

    <material name="red">
        <color rgba="0.8 0.1 0.1 1" />
    </material>

    <material name="grey">
        <color rgba="0.7 0.7 0.7 1" />
    </material>

    <material name="green">
        <color rgba="0.1 0.8 0.1 1" />
    </material>

    <material name="black">
        <color rgba="0 0 0 1" />
    </material>

    <!-- BASE LINK -->

    <link name="base_link">

    </link>

    <!-- CHASSIS LINK -->

    <joint name="chassis_joint" type="fixed">
        <parent link="base_link" />
        <child link="chassis" />
        <origin xyz="0 0 0.144" rpy="0 0 1.57079632679489" />
    </joint>

    <link name="chassis">
        <visual>
            <origin xyz="0 0 0" rpy="0 0 0" />
            <geometry>
                <mesh filename="package://lunabot_2425/stl/chassis.stl" />
            </geometry>
            <material name="white" />
        </visual>
        <collision>
            <origin xyz="0 0 0" rpy="0 0 0" />
            <geometry>
                <mesh filename="package://lunabot_2425/stl/chassis.stl" />
            </geometry>
        </collision>
        <inertial>
            <origin xyz="0.00047255856824676841735 0.0223648596978729651 0.13076886029956547031" rpy="0 0 0"/>
            <mass value="25" />
            <inertia ixx="0.90389242187733576106" ixy="0.0034717089339218617193"  ixz="-0.0076346994671778805816" iyy="0.40577362837262359596" iyz="-0.068059613649222985843" izz="0.9121615213756760765" />
        </inertial>
    </link>

    <!-- REAR LEFT WHEEL POD ASSEMBLY -->

    <joint name="rear_left_steer_joint" type="continuous">
        <parent link="chassis" />
        <child link="rear_left_pod" />
        <origin xyz="0.2655 0.2539125 0.0894" rpy="0 0 3.14159265358979" />
        <axis xyz="0 0 1" />
    </joint>

    <link name="rear_left_pod">
        <visual>
            <geometry>
                <mesh filename="package://lunabot_2425/stl/wheelpod.stl" />
            </geometry>
            <material name="red" />
        </visual>
        <collision>
            <geometry>
                <mesh filename="package://lunabot_2425/stl/wheelpod.stl" />
            </geometry>
        </collision>
        <inertial>
            <origin xyz="0.030048248825093670095 0 -0.054580062726334643841" rpy="0 0 0"/>
            <mass value="0.5" />
            <inertia ixx="0.0013087489021583560353" ixy="0"  ixz="0.00026671164402675704222" iyy="0.0013673630909145266868" iyz="0" izz="0.00042583920876048439019" />
        </inertial>
    </link>

    <joint name="rear_left_drive_joint" type="continuous">
        <parent link="rear_left_pod" />
        <child link="rear_left_wheel" />
        <origin xyz="0.0335 0 -0.13335" rpy="-1.57079632679489 0 3.14159265358979" />
        <axis xyz="1 0 0"/>
    </joint>

    <link name="rear_left_wheel">
        <visual>
            <geometry>
                <mesh filename="package://lunabot_2425/stl/wheel.stl" />
            </geometry>
            <material name="black" />
        </visual>
        <collision>
            <geometry>
                <mesh filename="package://lunabot_2425/stl/wheel.stl" />
            </geometry>
        </collision>
        <inertial>
            <origin xyz="0.03 0 0" rpy="0 0 0"/>
            <mass value="1" />
            <inertia ixx="0.0052" ixy="0" ixz="0" iyy="0.0029" iyz="0" izz="0.0029" />
        </inertial>
    </link>

    <!-- REAR RIGHT WHEEL POD ASSEMBLY -->

    <joint name="rear_right_steer_joint" type="continuous">
        <parent link="chassis" />
        <child link="rear_right_pod" />
        <origin xyz="-0.2655 0.2539125 0.0894" rpy="0 0 0" />
        <axis xyz="0 0 1" />
    </joint>

    <link name="rear_right_pod">
        <visual>
            <geometry>
                <mesh filename="package://lunabot_2425/stl/wheelpod.stl" />
            </geometry>
            <material name="red" />
        </visual>
        <collision>
            <geometry>
                <mesh filename="package://lunabot_2425/stl/wheelpod.stl" />
            </geometry>
        </collision>
        <inertial>
            <origin xyz="0.030048248825093670095 0 -0.054580062726334643841" rpy="0 0 0"/>
            <mass value="0.5" />
            <inertia ixx="0.0013087489021583560353" ixy="0"  ixz="0.00026671164402675704222" iyy="0.0013673630909145266868" iyz="0" izz="0.00042583920876048439019" />
        </inertial>
    </link>

    <joint name="rear_right_drive_joint" type="continuous">
        <parent link="rear_right_pod" />
        <child link="rear_right_wheel" />
        <origin xyz="0.0335 0 -0.13335" rpy="-1.57079632679489 0 3.14159265358979" />
        <axis xyz="-1 0 0"/>
    </joint>

    <link name="rear_right_wheel">
        <visual>
            <geometry>
                <mesh filename="package://lunabot_2425/stl/wheel.stl" />
            </geometry>
            <material name="black" />
        </visual>
        <collision>
            <geometry>
                <mesh filename="package://lunabot_2425/stl/wheel.stl" />
            </geometry>
        </collision>
        <inertial>
            <origin xyz="0.03 0 0" rpy="0 0 0"/>
            <mass value="1" />
            <inertia ixx="0.0052" ixy="0" ixz="0" iyy="0.0029" iyz="0" izz="0.0029" />
        </inertial>
    </link>

    <!-- FRONT LEFT WHEEL POD ASSEMBLY -->

    <joint name="front_left_steer_joint" type="continuous">
        <parent link="chassis" />
        <child link="front_left_pod" />
        <origin xyz="0.2655 -0.2539125 0.0894" rpy="0 0 3.14159265358979" />
        <axis xyz="0 0 1" />
    </joint>

    <link name="front_left_pod">
        <visual>
            <geometry>
                <mesh filename="package://lunabot_2425/stl/wheelpod.stl" />
            </geometry>
            <material name="red" />
        </visual>
        <collision>
            <geometry>
                <mesh filename="package://lunabot_2425/stl/wheelpod.stl" />
            </geometry>
        </collision>
        <inertial>
            <origin xyz="0.030048248825093670095 0 -0.054580062726334643841" rpy="0 0 0"/>
            <mass value="0.5" />
            <inertia ixx="0.0013087489021583560353" ixy="0"  ixz="0.00026671164402675704222" iyy="0.0013673630909145266868" iyz="0" izz="0.00042583920876048439019" />
        </inertial>
    </link>

    <joint name="front_left_drive_joint" type="continuous">
        <parent link="front_left_pod" />
        <child link="front_left_wheel" />
        <origin xyz="0.0335 0 -0.13335" rpy="-1.57079632679489 0 3.14159265358979" />
        <axis xyz="1 0 0"/>
    </joint>

    <link name="front_left_wheel">
        <visual>
            <geometry>
                <mesh filename="package://lunabot_2425/stl/wheel.stl" />
            </geometry>
            <material name="black" />
        </visual>
        <collision>
            <geometry>
                <mesh filename="package://lunabot_2425/stl/wheel.stl" />
            </geometry>
        </collision>
        <inertial>
            <origin xyz="0.03 0 0" rpy="0 0 0"/>
            <mass value="1" />
            <inertia ixx="0.0052" ixy="0" ixz="0" iyy="0.0029" iyz="0" izz="0.0029" />
        </inertial>
    </link>

    <!-- FRONT RIGHT WHEEL POD ASSEMBLY -->

    <joint name="front_right_steer_joint" type="continuous">
        <parent link="chassis" />
        <child link="front_right_pod" />
        <origin xyz="-0.2655 -0.2539125 0.0894" rpy="0 0 0" />
        <axis xyz="0 0 1" />
    </joint>

    <link name="front_right_pod">
        <visual>
            <geometry>
                <mesh filename="package://lunabot_2425/stl/wheelpod.stl" />
            </geometry>
            <material name="red" />
        </visual>
        <collision>
            <geometry>
                <mesh filename="package://lunabot_2425/stl/wheelpod.stl" />
            </geometry>
        </collision>
        <inertial>
            <origin xyz="0.030048248825093670095 0 -0.054580062726334643841" rpy="0 0 0"/>
            <mass value="0.5" />
            <inertia ixx="0.0013087489021583560353" ixy="0"  ixz="0.00026671164402675704222" iyy="0.0013673630909145266868" iyz="0" izz="0.00042583920876048439019" />
        </inertial>
    </link>

    <joint name="front_right_drive_joint" type="continuous">
        <parent link="front_right_pod" />
        <child link="front_right_wheel" />
        <origin xyz="0.0335 0 -0.13335" rpy="-1.57079632679489 0 3.14159265358979" />
        <axis xyz="-1 0 0"/>
    </joint>

    <link name="front_right_wheel">
        <visual>
            <geometry>
                <mesh filename="package://lunabot_2425/stl/wheel.stl" />
            </geometry>
            <material name="black" />
        </visual>
        <collision>
            <geometry>
                <mesh filename="package://lunabot_2425/stl/wheel.stl" />
            </geometry>
        </collision>
        <inertial>
            <origin xyz="0.03 0 0" rpy="0 0 0"/>
            <mass value="1" />
            <inertia ixx="0.0052" ixy="0" ixz="0" iyy="0.0029" iyz="0" izz="0.0029" />
        </inertial>
    </link>

</robot>
