<robot name="luna_urdf">
<link name="base_link"></link>
<joint name="base_link_to_base" type="fixed">
<parent link="base_link"/>
<child link="body" />
<origin rpy="0.0 0 0" xyz="0 0 0"/>
</joint>
<link name="body">
<visual>
<origin xyz="0 0 0" rpy="0 -0 0" />
<geometry>
<mesh filename="package://luna_urdf/luna_urdf/body.stl"/>
</geometry>
<material name="body_material">
<color rgba="0.61568627450980395466 0.81176470588235294379 0.92941176470588238168 1.0"/>
</material>
</visual>
<collision>
<origin xyz="0 0 0" rpy="0 -0 0" />
<geometry>
<mesh filename="package://luna_urdf/luna_urdf/body.stl"/>
</geometry>
</collision>
<inertial>
<origin xyz="0.00047255856824676874262 0.022364859697872972039 0.1307688602995654148" rpy="0 0 0"/>
<mass value="25" />
<inertia ixx="0.90389242187733476186" ixy="0.003471708933921862153"  ixz="-0.0076346994671779074698" iyy="0.40577362837262304085" iyz="-0.068059613649223027476" izz="0.91216152137567629854" />
</inertial>
</link>

<link name="wheelpod">
<visual>
<origin xyz="0 0 0" rpy="0 -0 0" />
<geometry>
<mesh filename="package://luna_urdf/luna_urdf/wheelpod.stl"/>
</geometry>
<material name="wheelpod_material">
<color rgba="0.61568627450980395466 0.81176470588235294379 0.92941176470588238168 1.0"/>
</material>
</visual>
<collision>
<origin xyz="0 0 0" rpy="0 -0 0" />
<geometry>
<mesh filename="package://luna_urdf/luna_urdf/wheelpod.stl"/>
</geometry>
</collision>
<inertial>
<origin xyz="0.030048248825093670095 1.0317928485796623683e-18 -0.054580062726334643841" rpy="0 0 0"/>
<mass value="0.49999999999999983347" />
<inertia ixx="0.0013087489021583556016" ixy="0"  ixz="0.00026671164402675698801" iyy="0.0013673630909145262531" iyz="0" izz="0.00042583920876048422756" />
</inertial>
</link>

<link name="wheel">
<visual>
<origin xyz="0 0 -0.05999999999999999778" rpy="-1.570796326794896558 -1.570796326794896558 0" />
<geometry>
<mesh filename="package://luna_urdf/luna_urdf/wheel.stl"/>
</geometry>
<material name="wheel_material">
<color rgba="0.61568627450980395466 0.81176470588235294379 0.92941176470588238168 1.0"/>
</material>
</visual>
<collision>
<origin xyz="0 0 -0.05999999999999999778" rpy="-1.570796326794896558 -1.570796326794896558 0" />
<geometry>
<mesh filename="package://luna_urdf/luna_urdf/wheel.stl"/>
</geometry>
</collision>
<inertial>
<origin xyz="2.2468246752869755867e-19 8.3413972423963372501e-18 -0.02999999999999999889" rpy="0 0 0"/>
<mass value="1" />
<inertia ixx="0.0029000000000000002338" ixy="0"  ixz="0" iyy="0.0028999999999999993665" iyz="0" izz="0.0052000000000000006287" />
</inertial>
</link>

<joint name="drive_br" type="revolute">
<origin xyz="0.033500000000000029754 0 -0.13334999999999999631" rpy="1.570796326794896558 -0 1.570796326794896558" />
<parent link="wheelpod" />
<child link="wheel" />
<axis xyz="0 0 1"/>
<limit effort="1" velocity="20" />
<joint_properties friction="0.0"/>
</joint>

<joint name="steer_br" type="revolute">
<origin xyz="-0.26550000000000006928 0.25391250000000009646 0.089399999999999979483" rpy="0 -0 0" />
<parent link="body" />
<child link="wheelpod" />
<axis xyz="0 0 1"/>
<limit effort="1" velocity="20" />
<joint_properties friction="0.0"/>
</joint>

<link name="wheelpod_2">
<visual>
<origin xyz="0 0 0" rpy="0 -0 0" />
<geometry>
<mesh filename="package://luna_urdf/luna_urdf/wheelpod.stl"/>
</geometry>
<material name="wheelpod_material">
<color rgba="0.61568627450980395466 0.81176470588235294379 0.92941176470588238168 1.0"/>
</material>
</visual>
<collision>
<origin xyz="0 0 0" rpy="0 -0 0" />
<geometry>
<mesh filename="package://luna_urdf/luna_urdf/wheelpod.stl"/>
</geometry>
</collision>
<inertial>
<origin xyz="0.030048248825093670095 1.0317928485796623683e-18 -0.054580062726334643841" rpy="0 0 0"/>
<mass value="0.49999999999999983347" />
<inertia ixx="0.0013087489021583556016" ixy="0"  ixz="0.00026671164402675698801" iyy="0.0013673630909145262531" iyz="0" izz="0.00042583920876048422756" />
</inertial>
</link>

<link name="wheel_2">
<visual>
<origin xyz="0 0 -0.05999999999999999778" rpy="-1.570796326794896558 -1.570796326794896558 0" />
<geometry>
<mesh filename="package://luna_urdf/luna_urdf/wheel.stl"/>
</geometry>
<material name="wheel_material">
<color rgba="0.61568627450980395466 0.81176470588235294379 0.92941176470588238168 1.0"/>
</material>
</visual>
<collision>
<origin xyz="0 0 -0.05999999999999999778" rpy="-1.570796326794896558 -1.570796326794896558 0" />
<geometry>
<mesh filename="package://luna_urdf/luna_urdf/wheel.stl"/>
</geometry>
</collision>
<inertial>
<origin xyz="2.2468246752869755867e-19 8.3413972423963372501e-18 -0.02999999999999999889" rpy="0 0 0"/>
<mass value="1" />
<inertia ixx="0.0029000000000000002338" ixy="0"  ixz="0" iyy="0.0028999999999999993665" iyz="0" izz="0.0052000000000000006287" />
</inertial>
</link>

<joint name="drive_fr" type="revolute">
<origin xyz="0.033500000000000029754 0 -0.13334999999999999631" rpy="1.570796326794896558 -0 1.570796326794896558" />
<parent link="wheelpod_2" />
<child link="wheel_2" />
<axis xyz="0 0 1"/>
<limit effort="1" velocity="20" />
<joint_properties friction="0.0"/>
</joint>

<joint name="steer_fr" type="revolute">
<origin xyz="-0.26550000000000006928 -0.25391249999999998543 0.089399999999999979483" rpy="0 -0 0" />
<parent link="body" />
<child link="wheelpod_2" />
<axis xyz="0 0 1"/>
<limit effort="1" velocity="20" />
<joint_properties friction="0.0"/>
</joint>

<link name="wheelpod_3">
<visual>
<origin xyz="0 0 0" rpy="0 -0 0" />
<geometry>
<mesh filename="package://luna_urdf/luna_urdf/wheelpod.stl"/>
</geometry>
<material name="wheelpod_material">
<color rgba="0.61568627450980395466 0.81176470588235294379 0.92941176470588238168 1.0"/>
</material>
</visual>
<collision>
<origin xyz="0 0 0" rpy="0 -0 0" />
<geometry>
<mesh filename="package://luna_urdf/luna_urdf/wheelpod.stl"/>
</geometry>
</collision>
<inertial>
<origin xyz="0.030048248825093670095 1.0317928485796623683e-18 -0.054580062726334643841" rpy="0 0 0"/>
<mass value="0.49999999999999983347" />
<inertia ixx="0.0013087489021583556016" ixy="0"  ixz="0.00026671164402675698801" iyy="0.0013673630909145262531" iyz="0" izz="0.00042583920876048422756" />
</inertial>
</link>

<link name="wheel_3">
<visual>
<origin xyz="0 0 0" rpy="1.570796326794896558 1.570796326794896558 0" />
<geometry>
<mesh filename="package://luna_urdf/luna_urdf/wheel.stl"/>
</geometry>
<material name="wheel_material">
<color rgba="0.61568627450980395466 0.81176470588235294379 0.92941176470588238168 1.0"/>
</material>
</visual>
<collision>
<origin xyz="0 0 0" rpy="1.570796326794896558 1.570796326794896558 0" />
<geometry>
<mesh filename="package://luna_urdf/luna_urdf/wheel.stl"/>
</geometry>
</collision>
<inertial>
<origin xyz="2.2468246752869755867e-19 -8.3413972423963372501e-18 -0.02999999999999999889" rpy="0 0 0"/>
<mass value="1" />
<inertia ixx="0.0029000000000000002338" ixy="0"  ixz="0" iyy="0.0028999999999999993665" iyz="0" izz="0.0052000000000000006287" />
</inertial>
</link>

<joint name="drive_fl" type="revolute">
<origin xyz="0.033500000000000001998 0 -0.13334999999999999631" rpy="-1.570796326794896558 -0 -1.570796326794896558" />
<parent link="wheelpod_3" />
<child link="wheel_3" />
<axis xyz="0 0 1"/>
<limit effort="1" velocity="20" />
<joint_properties friction="0.0"/>
</joint>

<joint name="steer_fl" type="revolute">
<origin xyz="0.26549999999999995826 -0.25391249999999998543 0.089399999999999979483" rpy="0 -0 3.141592653589793116" />
<parent link="body" />
<child link="wheelpod_3" />
<axis xyz="0 0 1"/>
<limit effort="1" velocity="20" />
<joint_properties friction="0.0"/>
</joint>

<link name="wheelpod_4">
<visual>
<origin xyz="0 0 0" rpy="0 -0 0" />
<geometry>
<mesh filename="package://luna_urdf/luna_urdf/wheelpod.stl"/>
</geometry>
<material name="wheelpod_material">
<color rgba="0.61568627450980395466 0.81176470588235294379 0.92941176470588238168 1.0"/>
</material>
</visual>
<collision>
<origin xyz="0 0 0" rpy="0 -0 0" />
<geometry>
<mesh filename="package://luna_urdf/luna_urdf/wheelpod.stl"/>
</geometry>
</collision>
<inertial>
<origin xyz="0.030048248825093670095 1.0317928485796623683e-18 -0.054580062726334643841" rpy="0 0 0"/>
<mass value="0.49999999999999983347" />
<inertia ixx="0.0013087489021583556016" ixy="0"  ixz="0.00026671164402675698801" iyy="0.0013673630909145262531" iyz="0" izz="0.00042583920876048422756" />
</inertial>
</link>

<link name="wheel_4">
<visual>
<origin xyz="0 0 0" rpy="1.570796326794896558 1.570796326794896558 0" />
<geometry>
<mesh filename="package://luna_urdf/luna_urdf/wheel.stl"/>
</geometry>
<material name="wheel_material">
<color rgba="0.61568627450980395466 0.81176470588235294379 0.92941176470588238168 1.0"/>
</material>
</visual>
<collision>
<origin xyz="0 0 0" rpy="1.570796326794896558 1.570796326794896558 0" />
<geometry>
<mesh filename="package://luna_urdf/luna_urdf/wheel.stl"/>
</geometry>
</collision>
<inertial>
<origin xyz="2.2468246752869755867e-19 -8.3413972423963372501e-18 -0.02999999999999999889" rpy="0 0 0"/>
<mass value="1" />
<inertia ixx="0.0029000000000000002338" ixy="0"  ixz="0" iyy="0.0028999999999999993665" iyz="0" izz="0.0052000000000000006287" />
</inertial>
</link>

<joint name="drive_bl" type="revolute">
<origin xyz="0.033500000000000001998 0 -0.13334999999999999631" rpy="-1.570796326794896558 -0 -1.570796326794896558" />
<parent link="wheelpod_4" />
<child link="wheel_4" />
<axis xyz="0 0 1"/>
<limit effort="1" velocity="20" />
<joint_properties friction="0.0"/>
</joint>

<joint name="steer_bl" type="revolute">
<origin xyz="0.26549999999999995826 0.25391250000000009646 0.089399999999999979483" rpy="0 -0 3.141592653589793116" />
<parent link="body" />
<child link="wheelpod_4" />
<axis xyz="0 0 1"/>
<limit effort="1" velocity="20" />
<joint_properties friction="0.0"/>
</joint>


</robot>
